Not Found: /
Not Found: /favicon.ico
Not Found: /users
Internal Server Error: /admin/
Traceback (most recent call last):
  File "/usr/local/lib/python3.7/site-packages/django/contrib/sessions/backends/base.py", line 199, in _get_session
    return self._session_cache
AttributeError: 'SessionStore' object has no attribute '_session_cache'

During handling of the above exception, another exception occurred:

Traceback (most recent call last):
  File "/usr/local/lib/python3.7/site-packages/django/db/backends/utils.py", line 86, in _execute
    return self.cursor.execute(sql, params)
psycopg2.errors.UndefinedTable: relation "django_session" does not exist
LINE 1: ...ession_data", "django_session"."expire_date" FROM "django_se...
                                                             ^


The above exception was the direct cause of the following exception:

Traceback (most recent call last):
  File "/usr/local/lib/python3.7/site-packages/django/core/handlers/exception.py", line 34, in inner
    response = get_response(request)
  File "/usr/local/lib/python3.7/site-packages/django/core/handlers/base.py", line 115, in _get_response
    response = self.process_exception_by_middleware(e, request)
  File "/usr/local/lib/python3.7/site-packages/django/core/handlers/base.py", line 113, in _get_response
    response = wrapped_callback(request, *callback_args, **callback_kwargs)
  File "/usr/local/lib/python3.7/site-packages/django/contrib/admin/sites.py", line 249, in wrapper
    return self.admin_view(view, cacheable)(*args, **kwargs)
  File "/usr/local/lib/python3.7/site-packages/django/utils/decorators.py", line 130, in _wrapped_view
    response = view_func(request, *args, **kwargs)
  File "/usr/local/lib/python3.7/site-packages/django/views/decorators/cache.py", line 44, in _wrapped_view_func
    response = view_func(request, *args, **kwargs)
  File "/usr/local/lib/python3.7/site-packages/django/contrib/admin/sites.py", line 220, in inner
    if not self.has_permission(request):
  File "/usr/local/lib/python3.7/site-packages/django/contrib/admin/sites.py", line 194, in has_permission
    return request.user.is_active and request.user.is_staff
  File "/usr/local/lib/python3.7/site-packages/django/utils/functional.py", line 224, in inner
    self._setup()
  File "/usr/local/lib/python3.7/site-packages/django/utils/functional.py", line 360, in _setup
    self._wrapped = self._setupfunc()
  File "/usr/local/lib/python3.7/site-packages/django/contrib/auth/middleware.py", line 24, in <lambda>
    request.user = SimpleLazyObject(lambda: get_user(request))
  File "/usr/local/lib/python3.7/site-packages/django/contrib/auth/middleware.py", line 12, in get_user
    request._cached_user = auth.get_user(request)
  File "/usr/local/lib/python3.7/site-packages/django/contrib/auth/__init__.py", line 173, in get_user
    user_id = _get_user_session_key(request)
  File "/usr/local/lib/python3.7/site-packages/django/contrib/auth/__init__.py", line 58, in _get_user_session_key
    return get_user_model()._meta.pk.to_python(request.session[SESSION_KEY])
  File "/usr/local/lib/python3.7/site-packages/django/contrib/sessions/backends/base.py", line 64, in __getitem__
    return self._session[key]
  File "/usr/local/lib/python3.7/site-packages/django/contrib/sessions/backends/base.py", line 204, in _get_session
    self._session_cache = self.load()
  File "/usr/local/lib/python3.7/site-packages/django/contrib/sessions/backends/db.py", line 43, in load
    s = self._get_session_from_db()
  File "/usr/local/lib/python3.7/site-packages/django/contrib/sessions/backends/db.py", line 34, in _get_session_from_db
    expire_date__gt=timezone.now()
  File "/usr/local/lib/python3.7/site-packages/django/db/models/manager.py", line 82, in manager_method
    return getattr(self.get_queryset(), name)(*args, **kwargs)
  File "/usr/local/lib/python3.7/site-packages/django/db/models/query.py", line 411, in get
    num = len(clone)
  File "/usr/local/lib/python3.7/site-packages/django/db/models/query.py", line 258, in __len__
    self._fetch_all()
  File "/usr/local/lib/python3.7/site-packages/django/db/models/query.py", line 1261, in _fetch_all
    self._result_cache = list(self._iterable_class(self))
  File "/usr/local/lib/python3.7/site-packages/django/db/models/query.py", line 57, in __iter__
    results = compiler.execute_sql(chunked_fetch=self.chunked_fetch, chunk_size=self.chunk_size)
  File "/usr/local/lib/python3.7/site-packages/django/db/models/sql/compiler.py", line 1144, in execute_sql
    cursor.execute(sql, params)
  File "/usr/local/lib/python3.7/site-packages/django/db/backends/utils.py", line 100, in execute
    return super().execute(sql, params)
  File "/usr/local/lib/python3.7/site-packages/django/db/backends/utils.py", line 68, in execute
    return self._execute_with_wrappers(sql, params, many=False, executor=self._execute)
  File "/usr/local/lib/python3.7/site-packages/django/db/backends/utils.py", line 77, in _execute_with_wrappers
    return executor(sql, params, many, context)
  File "/usr/local/lib/python3.7/site-packages/django/db/backends/utils.py", line 86, in _execute
    return self.cursor.execute(sql, params)
  File "/usr/local/lib/python3.7/site-packages/django/db/utils.py", line 90, in __exit__
    raise dj_exc_value.with_traceback(traceback) from exc_value
  File "/usr/local/lib/python3.7/site-packages/django/db/backends/utils.py", line 86, in _execute
    return self.cursor.execute(sql, params)
django.db.utils.ProgrammingError: relation "django_session" does not exist
LINE 1: ...ession_data", "django_session"."expire_date" FROM "django_se...
                                                             ^

Not Found: /
Internal Server Error: /admin/
Traceback (most recent call last):
  File "/usr/local/lib/python3.7/site-packages/django/contrib/sessions/backends/base.py", line 199, in _get_session
    return self._session_cache
AttributeError: 'SessionStore' object has no attribute '_session_cache'

During handling of the above exception, another exception occurred:

Traceback (most recent call last):
  File "/usr/local/lib/python3.7/site-packages/django/db/backends/utils.py", line 86, in _execute
    return self.cursor.execute(sql, params)
psycopg2.errors.UndefinedTable: relation "django_session" does not exist
LINE 1: ...ession_data", "django_session"."expire_date" FROM "django_se...
                                                             ^


The above exception was the direct cause of the following exception:

Traceback (most recent call last):
  File "/usr/local/lib/python3.7/site-packages/django/core/handlers/exception.py", line 34, in inner
    response = get_response(request)
  File "/usr/local/lib/python3.7/site-packages/django/core/handlers/base.py", line 115, in _get_response
    response = self.process_exception_by_middleware(e, request)
  File "/usr/local/lib/python3.7/site-packages/django/core/handlers/base.py", line 113, in _get_response
    response = wrapped_callback(request, *callback_args, **callback_kwargs)
  File "/usr/local/lib/python3.7/site-packages/django/contrib/admin/sites.py", line 249, in wrapper
    return self.admin_view(view, cacheable)(*args, **kwargs)
  File "/usr/local/lib/python3.7/site-packages/django/utils/decorators.py", line 130, in _wrapped_view
    response = view_func(request, *args, **kwargs)
  File "/usr/local/lib/python3.7/site-packages/django/views/decorators/cache.py", line 44, in _wrapped_view_func
    response = view_func(request, *args, **kwargs)
  File "/usr/local/lib/python3.7/site-packages/django/contrib/admin/sites.py", line 220, in inner
    if not self.has_permission(request):
  File "/usr/local/lib/python3.7/site-packages/django/contrib/admin/sites.py", line 194, in has_permission
    return request.user.is_active and request.user.is_staff
  File "/usr/local/lib/python3.7/site-packages/django/utils/functional.py", line 224, in inner
    self._setup()
  File "/usr/local/lib/python3.7/site-packages/django/utils/functional.py", line 360, in _setup
    self._wrapped = self._setupfunc()
  File "/usr/local/lib/python3.7/site-packages/django/contrib/auth/middleware.py", line 24, in <lambda>
    request.user = SimpleLazyObject(lambda: get_user(request))
  File "/usr/local/lib/python3.7/site-packages/django/contrib/auth/middleware.py", line 12, in get_user
    request._cached_user = auth.get_user(request)
  File "/usr/local/lib/python3.7/site-packages/django/contrib/auth/__init__.py", line 173, in get_user
    user_id = _get_user_session_key(request)
  File "/usr/local/lib/python3.7/site-packages/django/contrib/auth/__init__.py", line 58, in _get_user_session_key
    return get_user_model()._meta.pk.to_python(request.session[SESSION_KEY])
  File "/usr/local/lib/python3.7/site-packages/django/contrib/sessions/backends/base.py", line 64, in __getitem__
    return self._session[key]
  File "/usr/local/lib/python3.7/site-packages/django/contrib/sessions/backends/base.py", line 204, in _get_session
    self._session_cache = self.load()
  File "/usr/local/lib/python3.7/site-packages/django/contrib/sessions/backends/db.py", line 43, in load
    s = self._get_session_from_db()
  File "/usr/local/lib/python3.7/site-packages/django/contrib/sessions/backends/db.py", line 34, in _get_session_from_db
    expire_date__gt=timezone.now()
  File "/usr/local/lib/python3.7/site-packages/django/db/models/manager.py", line 82, in manager_method
    return getattr(self.get_queryset(), name)(*args, **kwargs)
  File "/usr/local/lib/python3.7/site-packages/django/db/models/query.py", line 411, in get
    num = len(clone)
  File "/usr/local/lib/python3.7/site-packages/django/db/models/query.py", line 258, in __len__
    self._fetch_all()
  File "/usr/local/lib/python3.7/site-packages/django/db/models/query.py", line 1261, in _fetch_all
    self._result_cache = list(self._iterable_class(self))
  File "/usr/local/lib/python3.7/site-packages/django/db/models/query.py", line 57, in __iter__
    results = compiler.execute_sql(chunked_fetch=self.chunked_fetch, chunk_size=self.chunk_size)
  File "/usr/local/lib/python3.7/site-packages/django/db/models/sql/compiler.py", line 1144, in execute_sql
    cursor.execute(sql, params)
  File "/usr/local/lib/python3.7/site-packages/django/db/backends/utils.py", line 100, in execute
    return super().execute(sql, params)
  File "/usr/local/lib/python3.7/site-packages/django/db/backends/utils.py", line 68, in execute
    return self._execute_with_wrappers(sql, params, many=False, executor=self._execute)
  File "/usr/local/lib/python3.7/site-packages/django/db/backends/utils.py", line 77, in _execute_with_wrappers
    return executor(sql, params, many, context)
  File "/usr/local/lib/python3.7/site-packages/django/db/backends/utils.py", line 86, in _execute
    return self.cursor.execute(sql, params)
  File "/usr/local/lib/python3.7/site-packages/django/db/utils.py", line 90, in __exit__
    raise dj_exc_value.with_traceback(traceback) from exc_value
  File "/usr/local/lib/python3.7/site-packages/django/db/backends/utils.py", line 86, in _execute
    return self.cursor.execute(sql, params)
django.db.utils.ProgrammingError: relation "django_session" does not exist
LINE 1: ...ession_data", "django_session"."expire_date" FROM "django_se...
                                                             ^

Not Found: /
Not Found: /admin/login/static/admin/css/base.css
Not Found: /admin/login/static/admin/css/responsive.css
Not Found: /admin/login/static/admin/css/login.css
Not Found: /admin/login/static/admin/css/responsive.css
Not Found: /admin/login/static/admin/css/base.css
Not Found: /admin/login/static/admin/css/login.css
Not Found: /users
Not Found: /admin/login/static/admin/css/login.css
Not Found: /admin/login/static/admin/css/base.css
Not Found: /admin/login/static/admin/css/responsive.css
Not Found: /admin/login/static/admin/css/base.css
Not Found: /admin/login/static/admin/css/responsive.css
Not Found: /admin/login/static/admin/css/login.css
Not Found: /
Not Found: /
Not Found: /
Not Found: /
Not Found: /favicon.ico
Not Found: /main.51b9a7b39d9fdbef0e83.hot-update.json
Not Found: /img/logo.svg
Not Found: /img/logo.svg
Not Found: /img/logo.svg
Not Found: /img/logo.svg
Not Found: /img/logo.svg
Not Found: /img/logo.svg
Not Found: /img/logo.svg
Not Found: /img/logo.svg
Not Found: /img/logo.svg
Not Found: /
Not Found: /favicon.ico
Not Found: /resources/illustrations/
Not Found: /resources/illustrations/landing_fitness_tracker.svg
Not Found: /resources/illustrations/landing_fitness_tracker.svg
Not Found: /resources/illustrations/landing_fitness_tracker
Not Found: /resources/illustrations/landing_fitness_tracker
Not Found: /resources/illustrations/landing_fitness_tracker
Not Found: /resources/illustrations/landing_fitness_tracker.svg
Not Found: /landing_fitness_tracker.svg
Not Found: /landing_fitness_tracker.svg
Not Found: /landing_fitness_tracker.svg
Not Found: /landing_fitness_tracker.svg
Not Found: /landing_fitness_tracker.svg
Not Found: /landing_fitness_tracker.svg
Not Found: /landing_fitness_tracker.svg
Not Found: /landing_fitness_tracker.svg
Not Found: /landing_fitness_tracker.svg
Not Found: /resources/illustrations/landing_fitness_tracker.svg
Not Found: /resources/illustrations/landing_fitness_tracker.svg
Not Found: /src/resources/illustrations/landing_fitness_tracker.svg
Not Found: /src/resources/illustrations/landing_fitness_tracker.svg
Not Found: /src/resources/illustrations/landing_fitness_tracker.svg
Not Found: /src/resources/illustrations/landing_fitness_tracker.svg
Not Found: /src/resources/illustrations/landing_fitness_tracker.svg
Not Found: /src/resources/illustrations/landing_fitness_tracker.svg
Not Found: /src/resources/illustrations/landing_fitness_tracker.svg
Not Found: /src/resources/illustrations/landing_fitness_tracker.svg
Not Found: /src/resources/illustrations/landing_fitness_tracker.svg
Not Found: /src/resources/illustrations/landing_fitness_tracker.svg
Not Found: /src/resources/illustrations/landing_fitness_tracker.svg
Not Found: /src/resources/illustrations/landing_fitness_tracker.svg
Not Found: /resources/illustrations/landing_fitness_tracker.svg
Not Found: /src/resources/illustrations/landing_fitness_tracker.svg
Not Found: /src/resources/illustrations/landing_fitness_tracker.svg
Not Found: /src/resources/illustrations/landing_fitness_tracker.svg
Not Found: /src/resources/illustrations/landing_fitness_tracker.svg
Not Found: /src/resources/illustrations/landing_fitness_tracker.svg
Not Found: /src/resources/illustrations/landing_fitness_tracker.svg
Not Found: /
Not Found: /favicon.ico
Not Found: /main.cf8925f6b06d6ad9ccf7.hot-update.json
Not Found: /
Not Found: /favicon.ico
Internal Server Error: /admin/login/
Traceback (most recent call last):
  File "/usr/local/lib/python3.7/site-packages/django/db/backends/utils.py", line 86, in _execute
    return self.cursor.execute(sql, params)
psycopg2.errors.UndefinedTable: relation "authentication_user" does not exist
LINE 1: ...", "authentication_user"."registration_date" FROM "authentic...
                                                             ^


The above exception was the direct cause of the following exception:

Traceback (most recent call last):
  File "/usr/local/lib/python3.7/site-packages/django/core/handlers/exception.py", line 34, in inner
    response = get_response(request)
  File "/usr/local/lib/python3.7/site-packages/django/core/handlers/base.py", line 115, in _get_response
    response = self.process_exception_by_middleware(e, request)
  File "/usr/local/lib/python3.7/site-packages/django/core/handlers/base.py", line 113, in _get_response
    response = wrapped_callback(request, *callback_args, **callback_kwargs)
  File "/usr/local/lib/python3.7/site-packages/django/views/decorators/cache.py", line 44, in _wrapped_view_func
    response = view_func(request, *args, **kwargs)
  File "/usr/local/lib/python3.7/site-packages/django/contrib/admin/sites.py", line 407, in login
    return LoginView.as_view(**defaults)(request)
  File "/usr/local/lib/python3.7/site-packages/django/views/generic/base.py", line 71, in view
    return self.dispatch(request, *args, **kwargs)
  File "/usr/local/lib/python3.7/site-packages/django/utils/decorators.py", line 43, in _wrapper
    return bound_method(*args, **kwargs)
  File "/usr/local/lib/python3.7/site-packages/django/views/decorators/debug.py", line 76, in sensitive_post_parameters_wrapper
    return view(request, *args, **kwargs)
  File "/usr/local/lib/python3.7/site-packages/django/utils/decorators.py", line 43, in _wrapper
    return bound_method(*args, **kwargs)
  File "/usr/local/lib/python3.7/site-packages/django/utils/decorators.py", line 130, in _wrapped_view
    response = view_func(request, *args, **kwargs)
  File "/usr/local/lib/python3.7/site-packages/django/utils/decorators.py", line 43, in _wrapper
    return bound_method(*args, **kwargs)
  File "/usr/local/lib/python3.7/site-packages/django/views/decorators/cache.py", line 44, in _wrapped_view_func
    response = view_func(request, *args, **kwargs)
  File "/usr/local/lib/python3.7/site-packages/django/contrib/auth/views.py", line 63, in dispatch
    return super().dispatch(request, *args, **kwargs)
  File "/usr/local/lib/python3.7/site-packages/django/views/generic/base.py", line 97, in dispatch
    return handler(request, *args, **kwargs)
  File "/usr/local/lib/python3.7/site-packages/django/views/generic/edit.py", line 141, in post
    if form.is_valid():
  File "/usr/local/lib/python3.7/site-packages/django/forms/forms.py", line 180, in is_valid
    return self.is_bound and not self.errors
  File "/usr/local/lib/python3.7/site-packages/django/forms/forms.py", line 175, in errors
    self.full_clean()
  File "/usr/local/lib/python3.7/site-packages/django/forms/forms.py", line 377, in full_clean
    self._clean_form()
  File "/usr/local/lib/python3.7/site-packages/django/forms/forms.py", line 404, in _clean_form
    cleaned_data = self.clean()
  File "/usr/local/lib/python3.7/site-packages/django/contrib/auth/forms.py", line 214, in clean
    self.user_cache = authenticate(self.request, username=username, password=password)
  File "/usr/local/lib/python3.7/site-packages/django/contrib/auth/__init__.py", line 72, in authenticate
    user = backend.authenticate(request, **credentials)
  File "/usr/local/lib/python3.7/site-packages/django/contrib/auth/backends.py", line 46, in authenticate
    user = UserModel._default_manager.get_by_natural_key(username)
  File "/usr/local/lib/python3.7/site-packages/django/contrib/auth/base_user.py", line 44, in get_by_natural_key
    return self.get(**{self.model.USERNAME_FIELD: username})
  File "/usr/local/lib/python3.7/site-packages/django/db/models/manager.py", line 82, in manager_method
    return getattr(self.get_queryset(), name)(*args, **kwargs)
  File "/usr/local/lib/python3.7/site-packages/django/db/models/query.py", line 411, in get
    num = len(clone)
  File "/usr/local/lib/python3.7/site-packages/django/db/models/query.py", line 258, in __len__
    self._fetch_all()
  File "/usr/local/lib/python3.7/site-packages/django/db/models/query.py", line 1261, in _fetch_all
    self._result_cache = list(self._iterable_class(self))
  File "/usr/local/lib/python3.7/site-packages/django/db/models/query.py", line 57, in __iter__
    results = compiler.execute_sql(chunked_fetch=self.chunked_fetch, chunk_size=self.chunk_size)
  File "/usr/local/lib/python3.7/site-packages/django/db/models/sql/compiler.py", line 1144, in execute_sql
    cursor.execute(sql, params)
  File "/usr/local/lib/python3.7/site-packages/django/db/backends/utils.py", line 100, in execute
    return super().execute(sql, params)
  File "/usr/local/lib/python3.7/site-packages/django/db/backends/utils.py", line 68, in execute
    return self._execute_with_wrappers(sql, params, many=False, executor=self._execute)
  File "/usr/local/lib/python3.7/site-packages/django/db/backends/utils.py", line 77, in _execute_with_wrappers
    return executor(sql, params, many, context)
  File "/usr/local/lib/python3.7/site-packages/django/db/backends/utils.py", line 86, in _execute
    return self.cursor.execute(sql, params)
  File "/usr/local/lib/python3.7/site-packages/django/db/utils.py", line 90, in __exit__
    raise dj_exc_value.with_traceback(traceback) from exc_value
  File "/usr/local/lib/python3.7/site-packages/django/db/backends/utils.py", line 86, in _execute
    return self.cursor.execute(sql, params)
django.db.utils.ProgrammingError: relation "authentication_user" does not exist
LINE 1: ...", "authentication_user"."registration_date" FROM "authentic...
                                                             ^

Not Found: /
Not Found: /favicon.ico
Not Found: /
Not Found: /api/
Internal Server Error: /authentication/
Traceback (most recent call last):
  File "C:\Users\CLEVO Computer\AppData\Local\Programs\Python\Python310\lib\site-packages\django\core\handlers\exception.py", line 55, in inner
    response = get_response(request)
  File "C:\Users\CLEVO Computer\AppData\Local\Programs\Python\Python310\lib\site-packages\django\core\handlers\base.py", line 197, in _get_response
    response = wrapped_callback(request, *callback_args, **callback_kwargs)
  File "C:\Users\CLEVO Computer\AppData\Local\Programs\Python\Python310\lib\site-packages\django\views\decorators\csrf.py", line 54, in wrapped_view
    return view_func(*args, **kwargs)
  File "C:\Users\CLEVO Computer\AppData\Local\Programs\Python\Python310\lib\site-packages\django\views\generic\base.py", line 103, in view
    return self.dispatch(request, *args, **kwargs)
  File "C:\Users\CLEVO Computer\AppData\Local\Programs\Python\Python310\lib\site-packages\rest_framework\views.py", line 492, in dispatch
    request = self.initialize_request(request, *args, **kwargs)
  File "C:\Users\CLEVO Computer\AppData\Local\Programs\Python\Python310\lib\site-packages\rest_framework\views.py", line 394, in initialize_request
    authenticators=self.get_authenticators(),
  File "C:\Users\CLEVO Computer\AppData\Local\Programs\Python\Python310\lib\site-packages\rest_framework\views.py", line 272, in get_authenticators
    return [auth() for auth in self.authentication_classes]
TypeError: 'type' object is not iterable
Internal Server Error: /authentication/
Traceback (most recent call last):
  File "C:\Users\CLEVO Computer\AppData\Local\Programs\Python\Python310\lib\site-packages\django\core\handlers\exception.py", line 55, in inner
    response = get_response(request)
  File "C:\Users\CLEVO Computer\AppData\Local\Programs\Python\Python310\lib\site-packages\django\core\handlers\base.py", line 197, in _get_response
    response = wrapped_callback(request, *callback_args, **callback_kwargs)
  File "C:\Users\CLEVO Computer\AppData\Local\Programs\Python\Python310\lib\site-packages\django\views\decorators\csrf.py", line 54, in wrapped_view
    return view_func(*args, **kwargs)
  File "C:\Users\CLEVO Computer\AppData\Local\Programs\Python\Python310\lib\site-packages\django\views\generic\base.py", line 103, in view
    return self.dispatch(request, *args, **kwargs)
  File "C:\Users\CLEVO Computer\AppData\Local\Programs\Python\Python310\lib\site-packages\rest_framework\views.py", line 492, in dispatch
    request = self.initialize_request(request, *args, **kwargs)
  File "C:\Users\CLEVO Computer\AppData\Local\Programs\Python\Python310\lib\site-packages\rest_framework\views.py", line 394, in initialize_request
    authenticators=self.get_authenticators(),
  File "C:\Users\CLEVO Computer\AppData\Local\Programs\Python\Python310\lib\site-packages\rest_framework\views.py", line 272, in get_authenticators
    return [auth() for auth in self.authentication_classes]
TypeError: 'type' object is not iterable
Method Not Allowed: /authentication/login/
Unauthorized: /authentication/login/
Method Not Allowed: /authentication/login/
Method Not Allowed: /authentication/register/
Bad Request: /authentication/register/
Bad Request: /authentication/register/
Unauthorized: /authentication/test/
Internal Server Error: /authentication/test
Traceback (most recent call last):
  File "C:\Users\CLEVO Computer\AppData\Local\Programs\Python\Python310\lib\site-packages\django\core\handlers\exception.py", line 55, in inner
    response = get_response(request)
  File "C:\Users\CLEVO Computer\AppData\Local\Programs\Python\Python310\lib\site-packages\django\utils\deprecation.py", line 135, in __call__
    response = self.process_request(request)
  File "C:\Users\CLEVO Computer\AppData\Local\Programs\Python\Python310\lib\site-packages\django\middleware\common.py", line 54, in process_request
    path = self.get_full_path_with_slash(request)
  File "C:\Users\CLEVO Computer\AppData\Local\Programs\Python\Python310\lib\site-packages\django\middleware\common.py", line 88, in get_full_path_with_slash
    raise RuntimeError(
RuntimeError: You called this URL via POST, but the URL doesn't end in a slash and you have APPEND_SLASH set. Django can't redirect to the slash URL while maintaining POST data. Change your form to point to localhost:8000/authentication/test/ (note the trailing slash), or set APPEND_SLASH=False in your Django settings.
Method Not Allowed: /authentication/login/
Internal Server Error: /authentication/test
Traceback (most recent call last):
  File "C:\Users\CLEVO Computer\AppData\Local\Programs\Python\Python310\lib\site-packages\django\core\handlers\exception.py", line 55, in inner
    response = get_response(request)
  File "C:\Users\CLEVO Computer\AppData\Local\Programs\Python\Python310\lib\site-packages\django\utils\deprecation.py", line 135, in __call__
    response = self.process_request(request)
  File "C:\Users\CLEVO Computer\AppData\Local\Programs\Python\Python310\lib\site-packages\django\middleware\common.py", line 54, in process_request
    path = self.get_full_path_with_slash(request)
  File "C:\Users\CLEVO Computer\AppData\Local\Programs\Python\Python310\lib\site-packages\django\middleware\common.py", line 88, in get_full_path_with_slash
    raise RuntimeError(
RuntimeError: You called this URL via POST, but the URL doesn't end in a slash and you have APPEND_SLASH set. Django can't redirect to the slash URL while maintaining POST data. Change your form to point to localhost:8000/authentication/test/ (note the trailing slash), or set APPEND_SLASH=False in your Django settings.
Internal Server Error: /authentication/test/
Traceback (most recent call last):
  File "C:\Users\CLEVO Computer\AppData\Local\Programs\Python\Python310\lib\site-packages\rest_framework\settings.py", line 177, in import_from_string
    return import_string(val)
  File "C:\Users\CLEVO Computer\AppData\Local\Programs\Python\Python310\lib\site-packages\django\utils\module_loading.py", line 30, in import_string
    return cached_import(module_path, class_name)
  File "C:\Users\CLEVO Computer\AppData\Local\Programs\Python\Python310\lib\site-packages\django\utils\module_loading.py", line 15, in cached_import
    module = import_module(module_path)
  File "C:\Users\CLEVO Computer\AppData\Local\Programs\Python\Python310\lib\importlib\__init__.py", line 126, in import_module
    return _bootstrap._gcd_import(name[level:], package, level)
  File "<frozen importlib._bootstrap>", line 1050, in _gcd_import
  File "<frozen importlib._bootstrap>", line 1027, in _find_and_load
  File "<frozen importlib._bootstrap>", line 1004, in _find_and_load_unlocked
ModuleNotFoundError: No module named 'rest_framework_simplejwt.token'

During handling of the above exception, another exception occurred:

Traceback (most recent call last):
  File "C:\Users\CLEVO Computer\AppData\Local\Programs\Python\Python310\lib\site-packages\django\core\handlers\exception.py", line 55, in inner
    response = get_response(request)
  File "C:\Users\CLEVO Computer\AppData\Local\Programs\Python\Python310\lib\site-packages\django\core\handlers\base.py", line 197, in _get_response
    response = wrapped_callback(request, *callback_args, **callback_kwargs)
  File "C:\Users\CLEVO Computer\AppData\Local\Programs\Python\Python310\lib\site-packages\django\views\decorators\csrf.py", line 54, in wrapped_view
    return view_func(*args, **kwargs)
  File "C:\Users\CLEVO Computer\AppData\Local\Programs\Python\Python310\lib\site-packages\django\views\generic\base.py", line 103, in view
    return self.dispatch(request, *args, **kwargs)
  File "C:\Users\CLEVO Computer\AppData\Local\Programs\Python\Python310\lib\site-packages\rest_framework\views.py", line 509, in dispatch
    response = self.handle_exception(exc)
  File "C:\Users\CLEVO Computer\AppData\Local\Programs\Python\Python310\lib\site-packages\rest_framework\views.py", line 469, in handle_exception
    self.raise_uncaught_exception(exc)
  File "C:\Users\CLEVO Computer\AppData\Local\Programs\Python\Python310\lib\site-packages\rest_framework\views.py", line 480, in raise_uncaught_exception
    raise exc
  File "C:\Users\CLEVO Computer\AppData\Local\Programs\Python\Python310\lib\site-packages\rest_framework\views.py", line 497, in dispatch
    self.initial(request, *args, **kwargs)
  File "C:\Users\CLEVO Computer\AppData\Local\Programs\Python\Python310\lib\site-packages\rest_framework\views.py", line 414, in initial
    self.perform_authentication(request)
  File "C:\Users\CLEVO Computer\AppData\Local\Programs\Python\Python310\lib\site-packages\rest_framework\views.py", line 324, in perform_authentication
    request.user
  File "C:\Users\CLEVO Computer\AppData\Local\Programs\Python\Python310\lib\site-packages\rest_framework\request.py", line 227, in user
    self._authenticate()
  File "C:\Users\CLEVO Computer\AppData\Local\Programs\Python\Python310\lib\site-packages\rest_framework\request.py", line 380, in _authenticate
    user_auth_tuple = authenticator.authenticate(self)
  File "C:\Users\CLEVO Computer\AppData\Local\Programs\Python\Python310\lib\site-packages\rest_framework_simplejwt\authentication.py", line 38, in authenticate
    validated_token = self.get_validated_token(raw_token)
  File "C:\Users\CLEVO Computer\AppData\Local\Programs\Python\Python310\lib\site-packages\rest_framework_simplejwt\authentication.py", line 90, in get_validated_token
    for AuthToken in api_settings.AUTH_TOKEN_CLASSES:
  File "C:\Users\CLEVO Computer\AppData\Local\Programs\Python\Python310\lib\site-packages\rest_framework\settings.py", line 225, in __getattr__
    val = perform_import(val, attr)
  File "C:\Users\CLEVO Computer\AppData\Local\Programs\Python\Python310\lib\site-packages\rest_framework\settings.py", line 168, in perform_import
    return [import_from_string(item, setting_name) for item in val]
  File "C:\Users\CLEVO Computer\AppData\Local\Programs\Python\Python310\lib\site-packages\rest_framework\settings.py", line 168, in <listcomp>
    return [import_from_string(item, setting_name) for item in val]
  File "C:\Users\CLEVO Computer\AppData\Local\Programs\Python\Python310\lib\site-packages\rest_framework\settings.py", line 180, in import_from_string
    raise ImportError(msg)
ImportError: Could not import 'rest_framework_simplejwt.token.AccessToken' for API setting 'AUTH_TOKEN_CLASSES'. ModuleNotFoundError: No module named 'rest_framework_simplejwt.token'.
Internal Server Error: /authentication/test/
Traceback (most recent call last):
  File "C:\Users\CLEVO Computer\AppData\Local\Programs\Python\Python310\lib\site-packages\rest_framework\settings.py", line 177, in import_from_string
    return import_string(val)
  File "C:\Users\CLEVO Computer\AppData\Local\Programs\Python\Python310\lib\site-packages\django\utils\module_loading.py", line 30, in import_string
    return cached_import(module_path, class_name)
  File "C:\Users\CLEVO Computer\AppData\Local\Programs\Python\Python310\lib\site-packages\django\utils\module_loading.py", line 15, in cached_import
    module = import_module(module_path)
  File "C:\Users\CLEVO Computer\AppData\Local\Programs\Python\Python310\lib\importlib\__init__.py", line 126, in import_module
    return _bootstrap._gcd_import(name[level:], package, level)
  File "<frozen importlib._bootstrap>", line 1050, in _gcd_import
  File "<frozen importlib._bootstrap>", line 1027, in _find_and_load
  File "<frozen importlib._bootstrap>", line 1004, in _find_and_load_unlocked
ModuleNotFoundError: No module named 'rest_framework_simplejwt.token'

During handling of the above exception, another exception occurred:

Traceback (most recent call last):
  File "C:\Users\CLEVO Computer\AppData\Local\Programs\Python\Python310\lib\site-packages\django\core\handlers\exception.py", line 55, in inner
    response = get_response(request)
  File "C:\Users\CLEVO Computer\AppData\Local\Programs\Python\Python310\lib\site-packages\django\core\handlers\base.py", line 197, in _get_response
    response = wrapped_callback(request, *callback_args, **callback_kwargs)
  File "C:\Users\CLEVO Computer\AppData\Local\Programs\Python\Python310\lib\site-packages\django\views\decorators\csrf.py", line 54, in wrapped_view
    return view_func(*args, **kwargs)
  File "C:\Users\CLEVO Computer\AppData\Local\Programs\Python\Python310\lib\site-packages\django\views\generic\base.py", line 103, in view
    return self.dispatch(request, *args, **kwargs)
  File "C:\Users\CLEVO Computer\AppData\Local\Programs\Python\Python310\lib\site-packages\rest_framework\views.py", line 509, in dispatch
    response = self.handle_exception(exc)
  File "C:\Users\CLEVO Computer\AppData\Local\Programs\Python\Python310\lib\site-packages\rest_framework\views.py", line 469, in handle_exception
    self.raise_uncaught_exception(exc)
  File "C:\Users\CLEVO Computer\AppData\Local\Programs\Python\Python310\lib\site-packages\rest_framework\views.py", line 480, in raise_uncaught_exception
    raise exc
  File "C:\Users\CLEVO Computer\AppData\Local\Programs\Python\Python310\lib\site-packages\rest_framework\views.py", line 497, in dispatch
    self.initial(request, *args, **kwargs)
  File "C:\Users\CLEVO Computer\AppData\Local\Programs\Python\Python310\lib\site-packages\rest_framework\views.py", line 414, in initial
    self.perform_authentication(request)
  File "C:\Users\CLEVO Computer\AppData\Local\Programs\Python\Python310\lib\site-packages\rest_framework\views.py", line 324, in perform_authentication
    request.user
  File "C:\Users\CLEVO Computer\AppData\Local\Programs\Python\Python310\lib\site-packages\rest_framework\request.py", line 227, in user
    self._authenticate()
  File "C:\Users\CLEVO Computer\AppData\Local\Programs\Python\Python310\lib\site-packages\rest_framework\request.py", line 380, in _authenticate
    user_auth_tuple = authenticator.authenticate(self)
  File "C:\Users\CLEVO Computer\AppData\Local\Programs\Python\Python310\lib\site-packages\rest_framework_simplejwt\authentication.py", line 38, in authenticate
    validated_token = self.get_validated_token(raw_token)
  File "C:\Users\CLEVO Computer\AppData\Local\Programs\Python\Python310\lib\site-packages\rest_framework_simplejwt\authentication.py", line 90, in get_validated_token
    for AuthToken in api_settings.AUTH_TOKEN_CLASSES:
  File "C:\Users\CLEVO Computer\AppData\Local\Programs\Python\Python310\lib\site-packages\rest_framework\settings.py", line 225, in __getattr__
    val = perform_import(val, attr)
  File "C:\Users\CLEVO Computer\AppData\Local\Programs\Python\Python310\lib\site-packages\rest_framework\settings.py", line 168, in perform_import
    return [import_from_string(item, setting_name) for item in val]
  File "C:\Users\CLEVO Computer\AppData\Local\Programs\Python\Python310\lib\site-packages\rest_framework\settings.py", line 168, in <listcomp>
    return [import_from_string(item, setting_name) for item in val]
  File "C:\Users\CLEVO Computer\AppData\Local\Programs\Python\Python310\lib\site-packages\rest_framework\settings.py", line 180, in import_from_string
    raise ImportError(msg)
ImportError: Could not import 'rest_framework_simplejwt.token.AccessToken' for API setting 'AUTH_TOKEN_CLASSES'. ModuleNotFoundError: No module named 'rest_framework_simplejwt.token'.
Internal Server Error: /authentication/test/
Traceback (most recent call last):
  File "C:\Users\CLEVO Computer\AppData\Local\Programs\Python\Python310\lib\site-packages\rest_framework\settings.py", line 177, in import_from_string
    return import_string(val)
  File "C:\Users\CLEVO Computer\AppData\Local\Programs\Python\Python310\lib\site-packages\django\utils\module_loading.py", line 30, in import_string
    return cached_import(module_path, class_name)
  File "C:\Users\CLEVO Computer\AppData\Local\Programs\Python\Python310\lib\site-packages\django\utils\module_loading.py", line 15, in cached_import
    module = import_module(module_path)
  File "C:\Users\CLEVO Computer\AppData\Local\Programs\Python\Python310\lib\importlib\__init__.py", line 126, in import_module
    return _bootstrap._gcd_import(name[level:], package, level)
  File "<frozen importlib._bootstrap>", line 1050, in _gcd_import
  File "<frozen importlib._bootstrap>", line 1027, in _find_and_load
  File "<frozen importlib._bootstrap>", line 1004, in _find_and_load_unlocked
ModuleNotFoundError: No module named 'rest_framework_simplejwt.token'

During handling of the above exception, another exception occurred:

Traceback (most recent call last):
  File "C:\Users\CLEVO Computer\AppData\Local\Programs\Python\Python310\lib\site-packages\django\core\handlers\exception.py", line 55, in inner
    response = get_response(request)
  File "C:\Users\CLEVO Computer\AppData\Local\Programs\Python\Python310\lib\site-packages\django\core\handlers\base.py", line 197, in _get_response
    response = wrapped_callback(request, *callback_args, **callback_kwargs)
  File "C:\Users\CLEVO Computer\AppData\Local\Programs\Python\Python310\lib\site-packages\django\views\decorators\csrf.py", line 54, in wrapped_view
    return view_func(*args, **kwargs)
  File "C:\Users\CLEVO Computer\AppData\Local\Programs\Python\Python310\lib\site-packages\django\views\generic\base.py", line 103, in view
    return self.dispatch(request, *args, **kwargs)
  File "C:\Users\CLEVO Computer\AppData\Local\Programs\Python\Python310\lib\site-packages\rest_framework\views.py", line 509, in dispatch
    response = self.handle_exception(exc)
  File "C:\Users\CLEVO Computer\AppData\Local\Programs\Python\Python310\lib\site-packages\rest_framework\views.py", line 469, in handle_exception
    self.raise_uncaught_exception(exc)
  File "C:\Users\CLEVO Computer\AppData\Local\Programs\Python\Python310\lib\site-packages\rest_framework\views.py", line 480, in raise_uncaught_exception
    raise exc
  File "C:\Users\CLEVO Computer\AppData\Local\Programs\Python\Python310\lib\site-packages\rest_framework\views.py", line 497, in dispatch
    self.initial(request, *args, **kwargs)
  File "C:\Users\CLEVO Computer\AppData\Local\Programs\Python\Python310\lib\site-packages\rest_framework\views.py", line 414, in initial
    self.perform_authentication(request)
  File "C:\Users\CLEVO Computer\AppData\Local\Programs\Python\Python310\lib\site-packages\rest_framework\views.py", line 324, in perform_authentication
    request.user
  File "C:\Users\CLEVO Computer\AppData\Local\Programs\Python\Python310\lib\site-packages\rest_framework\request.py", line 227, in user
    self._authenticate()
  File "C:\Users\CLEVO Computer\AppData\Local\Programs\Python\Python310\lib\site-packages\rest_framework\request.py", line 380, in _authenticate
    user_auth_tuple = authenticator.authenticate(self)
  File "C:\Users\CLEVO Computer\AppData\Local\Programs\Python\Python310\lib\site-packages\rest_framework_simplejwt\authentication.py", line 38, in authenticate
    validated_token = self.get_validated_token(raw_token)
  File "C:\Users\CLEVO Computer\AppData\Local\Programs\Python\Python310\lib\site-packages\rest_framework_simplejwt\authentication.py", line 90, in get_validated_token
    for AuthToken in api_settings.AUTH_TOKEN_CLASSES:
  File "C:\Users\CLEVO Computer\AppData\Local\Programs\Python\Python310\lib\site-packages\rest_framework\settings.py", line 225, in __getattr__
    val = perform_import(val, attr)
  File "C:\Users\CLEVO Computer\AppData\Local\Programs\Python\Python310\lib\site-packages\rest_framework\settings.py", line 168, in perform_import
    return [import_from_string(item, setting_name) for item in val]
  File "C:\Users\CLEVO Computer\AppData\Local\Programs\Python\Python310\lib\site-packages\rest_framework\settings.py", line 168, in <listcomp>
    return [import_from_string(item, setting_name) for item in val]
  File "C:\Users\CLEVO Computer\AppData\Local\Programs\Python\Python310\lib\site-packages\rest_framework\settings.py", line 180, in import_from_string
    raise ImportError(msg)
ImportError: Could not import 'rest_framework_simplejwt.token.AccessToken' for API setting 'AUTH_TOKEN_CLASSES'. ModuleNotFoundError: No module named 'rest_framework_simplejwt.token'.
Unauthorized: /authentication/test/
Internal Server Error: /authentication/test/
Traceback (most recent call last):
  File "C:\Users\CLEVO Computer\AppData\Local\Programs\Python\Python310\lib\site-packages\rest_framework\settings.py", line 177, in import_from_string
    return import_string(val)
  File "C:\Users\CLEVO Computer\AppData\Local\Programs\Python\Python310\lib\site-packages\django\utils\module_loading.py", line 30, in import_string
    return cached_import(module_path, class_name)
  File "C:\Users\CLEVO Computer\AppData\Local\Programs\Python\Python310\lib\site-packages\django\utils\module_loading.py", line 15, in cached_import
    module = import_module(module_path)
  File "C:\Users\CLEVO Computer\AppData\Local\Programs\Python\Python310\lib\importlib\__init__.py", line 126, in import_module
    return _bootstrap._gcd_import(name[level:], package, level)
  File "<frozen importlib._bootstrap>", line 1050, in _gcd_import
  File "<frozen importlib._bootstrap>", line 1027, in _find_and_load
  File "<frozen importlib._bootstrap>", line 1004, in _find_and_load_unlocked
ModuleNotFoundError: No module named 'rest_framework_simplejwt.token'

During handling of the above exception, another exception occurred:

Traceback (most recent call last):
  File "C:\Users\CLEVO Computer\AppData\Local\Programs\Python\Python310\lib\site-packages\django\core\handlers\exception.py", line 55, in inner
    response = get_response(request)
  File "C:\Users\CLEVO Computer\AppData\Local\Programs\Python\Python310\lib\site-packages\django\core\handlers\base.py", line 197, in _get_response
    response = wrapped_callback(request, *callback_args, **callback_kwargs)
  File "C:\Users\CLEVO Computer\AppData\Local\Programs\Python\Python310\lib\site-packages\django\views\decorators\csrf.py", line 54, in wrapped_view
    return view_func(*args, **kwargs)
  File "C:\Users\CLEVO Computer\AppData\Local\Programs\Python\Python310\lib\site-packages\django\views\generic\base.py", line 103, in view
    return self.dispatch(request, *args, **kwargs)
  File "C:\Users\CLEVO Computer\AppData\Local\Programs\Python\Python310\lib\site-packages\rest_framework\views.py", line 509, in dispatch
    response = self.handle_exception(exc)
  File "C:\Users\CLEVO Computer\AppData\Local\Programs\Python\Python310\lib\site-packages\rest_framework\views.py", line 469, in handle_exception
    self.raise_uncaught_exception(exc)
  File "C:\Users\CLEVO Computer\AppData\Local\Programs\Python\Python310\lib\site-packages\rest_framework\views.py", line 480, in raise_uncaught_exception
    raise exc
  File "C:\Users\CLEVO Computer\AppData\Local\Programs\Python\Python310\lib\site-packages\rest_framework\views.py", line 497, in dispatch
    self.initial(request, *args, **kwargs)
  File "C:\Users\CLEVO Computer\AppData\Local\Programs\Python\Python310\lib\site-packages\rest_framework\views.py", line 414, in initial
    self.perform_authentication(request)
  File "C:\Users\CLEVO Computer\AppData\Local\Programs\Python\Python310\lib\site-packages\rest_framework\views.py", line 324, in perform_authentication
    request.user
  File "C:\Users\CLEVO Computer\AppData\Local\Programs\Python\Python310\lib\site-packages\rest_framework\request.py", line 227, in user
    self._authenticate()
  File "C:\Users\CLEVO Computer\AppData\Local\Programs\Python\Python310\lib\site-packages\rest_framework\request.py", line 380, in _authenticate
    user_auth_tuple = authenticator.authenticate(self)
  File "C:\Users\CLEVO Computer\AppData\Local\Programs\Python\Python310\lib\site-packages\rest_framework_simplejwt\authentication.py", line 38, in authenticate
    validated_token = self.get_validated_token(raw_token)
  File "C:\Users\CLEVO Computer\AppData\Local\Programs\Python\Python310\lib\site-packages\rest_framework_simplejwt\authentication.py", line 90, in get_validated_token
    for AuthToken in api_settings.AUTH_TOKEN_CLASSES:
  File "C:\Users\CLEVO Computer\AppData\Local\Programs\Python\Python310\lib\site-packages\rest_framework\settings.py", line 225, in __getattr__
    val = perform_import(val, attr)
  File "C:\Users\CLEVO Computer\AppData\Local\Programs\Python\Python310\lib\site-packages\rest_framework\settings.py", line 168, in perform_import
    return [import_from_string(item, setting_name) for item in val]
  File "C:\Users\CLEVO Computer\AppData\Local\Programs\Python\Python310\lib\site-packages\rest_framework\settings.py", line 168, in <listcomp>
    return [import_from_string(item, setting_name) for item in val]
  File "C:\Users\CLEVO Computer\AppData\Local\Programs\Python\Python310\lib\site-packages\rest_framework\settings.py", line 180, in import_from_string
    raise ImportError(msg)
ImportError: Could not import 'rest_framework_simplejwt.token.AccessToken' for API setting 'AUTH_TOKEN_CLASSES'. ModuleNotFoundError: No module named 'rest_framework_simplejwt.token'.
Internal Server Error: /authentication/test/
Traceback (most recent call last):
  File "C:\Users\CLEVO Computer\AppData\Local\Programs\Python\Python310\lib\site-packages\rest_framework\settings.py", line 177, in import_from_string
    return import_string(val)
  File "C:\Users\CLEVO Computer\AppData\Local\Programs\Python\Python310\lib\site-packages\django\utils\module_loading.py", line 30, in import_string
    return cached_import(module_path, class_name)
  File "C:\Users\CLEVO Computer\AppData\Local\Programs\Python\Python310\lib\site-packages\django\utils\module_loading.py", line 15, in cached_import
    module = import_module(module_path)
  File "C:\Users\CLEVO Computer\AppData\Local\Programs\Python\Python310\lib\importlib\__init__.py", line 126, in import_module
    return _bootstrap._gcd_import(name[level:], package, level)
  File "<frozen importlib._bootstrap>", line 1050, in _gcd_import
  File "<frozen importlib._bootstrap>", line 1027, in _find_and_load
  File "<frozen importlib._bootstrap>", line 1004, in _find_and_load_unlocked
ModuleNotFoundError: No module named 'rest_framework_simplejwt.token'

During handling of the above exception, another exception occurred:

Traceback (most recent call last):
  File "C:\Users\CLEVO Computer\AppData\Local\Programs\Python\Python310\lib\site-packages\django\core\handlers\exception.py", line 55, in inner
    response = get_response(request)
  File "C:\Users\CLEVO Computer\AppData\Local\Programs\Python\Python310\lib\site-packages\django\core\handlers\base.py", line 197, in _get_response
    response = wrapped_callback(request, *callback_args, **callback_kwargs)
  File "C:\Users\CLEVO Computer\AppData\Local\Programs\Python\Python310\lib\site-packages\django\views\decorators\csrf.py", line 54, in wrapped_view
    return view_func(*args, **kwargs)
  File "C:\Users\CLEVO Computer\AppData\Local\Programs\Python\Python310\lib\site-packages\django\views\generic\base.py", line 103, in view
    return self.dispatch(request, *args, **kwargs)
  File "C:\Users\CLEVO Computer\AppData\Local\Programs\Python\Python310\lib\site-packages\rest_framework\views.py", line 509, in dispatch
    response = self.handle_exception(exc)
  File "C:\Users\CLEVO Computer\AppData\Local\Programs\Python\Python310\lib\site-packages\rest_framework\views.py", line 469, in handle_exception
    self.raise_uncaught_exception(exc)
  File "C:\Users\CLEVO Computer\AppData\Local\Programs\Python\Python310\lib\site-packages\rest_framework\views.py", line 480, in raise_uncaught_exception
    raise exc
  File "C:\Users\CLEVO Computer\AppData\Local\Programs\Python\Python310\lib\site-packages\rest_framework\views.py", line 497, in dispatch
    self.initial(request, *args, **kwargs)
  File "C:\Users\CLEVO Computer\AppData\Local\Programs\Python\Python310\lib\site-packages\rest_framework\views.py", line 414, in initial
    self.perform_authentication(request)
  File "C:\Users\CLEVO Computer\AppData\Local\Programs\Python\Python310\lib\site-packages\rest_framework\views.py", line 324, in perform_authentication
    request.user
  File "C:\Users\CLEVO Computer\AppData\Local\Programs\Python\Python310\lib\site-packages\rest_framework\request.py", line 227, in user
    self._authenticate()
  File "C:\Users\CLEVO Computer\AppData\Local\Programs\Python\Python310\lib\site-packages\rest_framework\request.py", line 380, in _authenticate
    user_auth_tuple = authenticator.authenticate(self)
  File "C:\Users\CLEVO Computer\AppData\Local\Programs\Python\Python310\lib\site-packages\rest_framework_simplejwt\authentication.py", line 38, in authenticate
    validated_token = self.get_validated_token(raw_token)
  File "C:\Users\CLEVO Computer\AppData\Local\Programs\Python\Python310\lib\site-packages\rest_framework_simplejwt\authentication.py", line 90, in get_validated_token
    for AuthToken in api_settings.AUTH_TOKEN_CLASSES:
  File "C:\Users\CLEVO Computer\AppData\Local\Programs\Python\Python310\lib\site-packages\rest_framework\settings.py", line 225, in __getattr__
    val = perform_import(val, attr)
  File "C:\Users\CLEVO Computer\AppData\Local\Programs\Python\Python310\lib\site-packages\rest_framework\settings.py", line 168, in perform_import
    return [import_from_string(item, setting_name) for item in val]
  File "C:\Users\CLEVO Computer\AppData\Local\Programs\Python\Python310\lib\site-packages\rest_framework\settings.py", line 168, in <listcomp>
    return [import_from_string(item, setting_name) for item in val]
  File "C:\Users\CLEVO Computer\AppData\Local\Programs\Python\Python310\lib\site-packages\rest_framework\settings.py", line 180, in import_from_string
    raise ImportError(msg)
ImportError: Could not import 'rest_framework_simplejwt.token.AccessToken' for API setting 'AUTH_TOKEN_CLASSES'. ModuleNotFoundError: No module named 'rest_framework_simplejwt.token'.
Internal Server Error: /authentication/
Traceback (most recent call last):
  File "C:\Users\CLEVO Computer\AppData\Local\Programs\Python\Python310\lib\site-packages\rest_framework\settings.py", line 177, in import_from_string
    return import_string(val)
  File "C:\Users\CLEVO Computer\AppData\Local\Programs\Python\Python310\lib\site-packages\django\utils\module_loading.py", line 30, in import_string
    return cached_import(module_path, class_name)
  File "C:\Users\CLEVO Computer\AppData\Local\Programs\Python\Python310\lib\site-packages\django\utils\module_loading.py", line 15, in cached_import
    module = import_module(module_path)
  File "C:\Users\CLEVO Computer\AppData\Local\Programs\Python\Python310\lib\importlib\__init__.py", line 126, in import_module
    return _bootstrap._gcd_import(name[level:], package, level)
  File "<frozen importlib._bootstrap>", line 1050, in _gcd_import
  File "<frozen importlib._bootstrap>", line 1027, in _find_and_load
  File "<frozen importlib._bootstrap>", line 1004, in _find_and_load_unlocked
ModuleNotFoundError: No module named 'rest_framework_simplejwt.token'

During handling of the above exception, another exception occurred:

Traceback (most recent call last):
  File "C:\Users\CLEVO Computer\AppData\Local\Programs\Python\Python310\lib\site-packages\django\core\handlers\exception.py", line 55, in inner
    response = get_response(request)
  File "C:\Users\CLEVO Computer\AppData\Local\Programs\Python\Python310\lib\site-packages\django\core\handlers\base.py", line 197, in _get_response
    response = wrapped_callback(request, *callback_args, **callback_kwargs)
  File "C:\Users\CLEVO Computer\AppData\Local\Programs\Python\Python310\lib\site-packages\django\views\decorators\csrf.py", line 54, in wrapped_view
    return view_func(*args, **kwargs)
  File "C:\Users\CLEVO Computer\AppData\Local\Programs\Python\Python310\lib\site-packages\django\views\generic\base.py", line 103, in view
    return self.dispatch(request, *args, **kwargs)
  File "C:\Users\CLEVO Computer\AppData\Local\Programs\Python\Python310\lib\site-packages\rest_framework\views.py", line 509, in dispatch
    response = self.handle_exception(exc)
  File "C:\Users\CLEVO Computer\AppData\Local\Programs\Python\Python310\lib\site-packages\rest_framework\views.py", line 469, in handle_exception
    self.raise_uncaught_exception(exc)
  File "C:\Users\CLEVO Computer\AppData\Local\Programs\Python\Python310\lib\site-packages\rest_framework\views.py", line 480, in raise_uncaught_exception
    raise exc
  File "C:\Users\CLEVO Computer\AppData\Local\Programs\Python\Python310\lib\site-packages\rest_framework\views.py", line 497, in dispatch
    self.initial(request, *args, **kwargs)
  File "C:\Users\CLEVO Computer\AppData\Local\Programs\Python\Python310\lib\site-packages\rest_framework\views.py", line 414, in initial
    self.perform_authentication(request)
  File "C:\Users\CLEVO Computer\AppData\Local\Programs\Python\Python310\lib\site-packages\rest_framework\views.py", line 324, in perform_authentication
    request.user
  File "C:\Users\CLEVO Computer\AppData\Local\Programs\Python\Python310\lib\site-packages\rest_framework\request.py", line 227, in user
    self._authenticate()
  File "C:\Users\CLEVO Computer\AppData\Local\Programs\Python\Python310\lib\site-packages\rest_framework\request.py", line 380, in _authenticate
    user_auth_tuple = authenticator.authenticate(self)
  File "C:\Users\CLEVO Computer\AppData\Local\Programs\Python\Python310\lib\site-packages\rest_framework_simplejwt\authentication.py", line 38, in authenticate
    validated_token = self.get_validated_token(raw_token)
  File "C:\Users\CLEVO Computer\AppData\Local\Programs\Python\Python310\lib\site-packages\rest_framework_simplejwt\authentication.py", line 90, in get_validated_token
    for AuthToken in api_settings.AUTH_TOKEN_CLASSES:
  File "C:\Users\CLEVO Computer\AppData\Local\Programs\Python\Python310\lib\site-packages\rest_framework\settings.py", line 225, in __getattr__
    val = perform_import(val, attr)
  File "C:\Users\CLEVO Computer\AppData\Local\Programs\Python\Python310\lib\site-packages\rest_framework\settings.py", line 168, in perform_import
    return [import_from_string(item, setting_name) for item in val]
  File "C:\Users\CLEVO Computer\AppData\Local\Programs\Python\Python310\lib\site-packages\rest_framework\settings.py", line 168, in <listcomp>
    return [import_from_string(item, setting_name) for item in val]
  File "C:\Users\CLEVO Computer\AppData\Local\Programs\Python\Python310\lib\site-packages\rest_framework\settings.py", line 180, in import_from_string
    raise ImportError(msg)
ImportError: Could not import 'rest_framework_simplejwt.token.AccessToken' for API setting 'AUTH_TOKEN_CLASSES'. ModuleNotFoundError: No module named 'rest_framework_simplejwt.token'.
Unauthorized: /authentication/test/
Method Not Allowed: /authentication/login/
Internal Server Error: /authentication/test/
Traceback (most recent call last):
  File "C:\Users\CLEVO Computer\AppData\Local\Programs\Python\Python310\lib\site-packages\rest_framework\settings.py", line 177, in import_from_string
    return import_string(val)
  File "C:\Users\CLEVO Computer\AppData\Local\Programs\Python\Python310\lib\site-packages\django\utils\module_loading.py", line 30, in import_string
    return cached_import(module_path, class_name)
  File "C:\Users\CLEVO Computer\AppData\Local\Programs\Python\Python310\lib\site-packages\django\utils\module_loading.py", line 15, in cached_import
    module = import_module(module_path)
  File "C:\Users\CLEVO Computer\AppData\Local\Programs\Python\Python310\lib\importlib\__init__.py", line 126, in import_module
    return _bootstrap._gcd_import(name[level:], package, level)
  File "<frozen importlib._bootstrap>", line 1050, in _gcd_import
  File "<frozen importlib._bootstrap>", line 1027, in _find_and_load
  File "<frozen importlib._bootstrap>", line 1004, in _find_and_load_unlocked
ModuleNotFoundError: No module named 'rest_framework_simplejwt.token'

During handling of the above exception, another exception occurred:

Traceback (most recent call last):
  File "C:\Users\CLEVO Computer\AppData\Local\Programs\Python\Python310\lib\site-packages\django\core\handlers\exception.py", line 55, in inner
    response = get_response(request)
  File "C:\Users\CLEVO Computer\AppData\Local\Programs\Python\Python310\lib\site-packages\django\core\handlers\base.py", line 197, in _get_response
    response = wrapped_callback(request, *callback_args, **callback_kwargs)
  File "C:\Users\CLEVO Computer\AppData\Local\Programs\Python\Python310\lib\site-packages\django\views\decorators\csrf.py", line 54, in wrapped_view
    return view_func(*args, **kwargs)
  File "C:\Users\CLEVO Computer\AppData\Local\Programs\Python\Python310\lib\site-packages\django\views\generic\base.py", line 103, in view
    return self.dispatch(request, *args, **kwargs)
  File "C:\Users\CLEVO Computer\AppData\Local\Programs\Python\Python310\lib\site-packages\rest_framework\views.py", line 509, in dispatch
    response = self.handle_exception(exc)
  File "C:\Users\CLEVO Computer\AppData\Local\Programs\Python\Python310\lib\site-packages\rest_framework\views.py", line 469, in handle_exception
    self.raise_uncaught_exception(exc)
  File "C:\Users\CLEVO Computer\AppData\Local\Programs\Python\Python310\lib\site-packages\rest_framework\views.py", line 480, in raise_uncaught_exception
    raise exc
  File "C:\Users\CLEVO Computer\AppData\Local\Programs\Python\Python310\lib\site-packages\rest_framework\views.py", line 497, in dispatch
    self.initial(request, *args, **kwargs)
  File "C:\Users\CLEVO Computer\AppData\Local\Programs\Python\Python310\lib\site-packages\rest_framework\views.py", line 414, in initial
    self.perform_authentication(request)
  File "C:\Users\CLEVO Computer\AppData\Local\Programs\Python\Python310\lib\site-packages\rest_framework\views.py", line 324, in perform_authentication
    request.user
  File "C:\Users\CLEVO Computer\AppData\Local\Programs\Python\Python310\lib\site-packages\rest_framework\request.py", line 227, in user
    self._authenticate()
  File "C:\Users\CLEVO Computer\AppData\Local\Programs\Python\Python310\lib\site-packages\rest_framework\request.py", line 380, in _authenticate
    user_auth_tuple = authenticator.authenticate(self)
  File "C:\Users\CLEVO Computer\AppData\Local\Programs\Python\Python310\lib\site-packages\rest_framework_simplejwt\authentication.py", line 38, in authenticate
    validated_token = self.get_validated_token(raw_token)
  File "C:\Users\CLEVO Computer\AppData\Local\Programs\Python\Python310\lib\site-packages\rest_framework_simplejwt\authentication.py", line 90, in get_validated_token
    for AuthToken in api_settings.AUTH_TOKEN_CLASSES:
  File "C:\Users\CLEVO Computer\AppData\Local\Programs\Python\Python310\lib\site-packages\rest_framework\settings.py", line 225, in __getattr__
    val = perform_import(val, attr)
  File "C:\Users\CLEVO Computer\AppData\Local\Programs\Python\Python310\lib\site-packages\rest_framework\settings.py", line 168, in perform_import
    return [import_from_string(item, setting_name) for item in val]
  File "C:\Users\CLEVO Computer\AppData\Local\Programs\Python\Python310\lib\site-packages\rest_framework\settings.py", line 168, in <listcomp>
    return [import_from_string(item, setting_name) for item in val]
  File "C:\Users\CLEVO Computer\AppData\Local\Programs\Python\Python310\lib\site-packages\rest_framework\settings.py", line 180, in import_from_string
    raise ImportError(msg)
ImportError: Could not import 'rest_framework_simplejwt.token.AccessToken' for API setting 'AUTH_TOKEN_CLASSES'. ModuleNotFoundError: No module named 'rest_framework_simplejwt.token'.
Unauthorized: /authentication/test/
Unauthorized: /authentication/test/
Not Found: /
Not Found: /favicon.ico
Method Not Allowed: /authentication/refresh-token/
Method Not Allowed: /authentication/register/
Bad Request: /authentication/login/
Not Found: /
Not Found: /favicon.ico
Method Not Allowed: /authentication/login/
Bad Request: /authentication/login/
Bad Request: /authentication/login/
Bad Request: /authentication/login/
Method Not Allowed: /authentication/login/
Bad Request: /authentication/login/
Bad Request: /authentication/login/
Bad Request: /authentication/login/
Bad Request: /authentication/login/
Not Found: /
Method Not Allowed: /authentication/login/
Unauthorized: /authentication/login/
Bad Request: /authentication/register/
Method Not Allowed: /authentication/register/
Bad Request: /authentication/register/
Bad Request: /authentication/register/
Bad Request: /authentication/register/
Bad Request: /authentication/register/
Bad Request: /authentication/register/
Bad Request: /authentication/register/
Bad Request: /authentication/register/
Bad Request: /authentication/register/
Not Found: /authentication//refresh-token/
Bad Request: /authentication/register/
Bad Request: /authentication/register/
Bad Request: /authentication/register/
Bad Request: /authentication/register/
Bad Request: /authentication/register/
Bad Request: /authentication/register/
Bad Request: /authentication/register/
Bad Request: /authentication/register/
Unauthorized: /authentication/login/
Unauthorized: /authentication/login/
Not Found: /
Not Found: /favicon.ico
Unauthorized: /workout
Unauthorized: /workout
Unauthorized: /workout
Unauthorized: /workout
Unauthorized: /workout
Unauthorized: /workout
Unauthorized: /workout
Unauthorized: /workout
Unauthorized: /workout
Not Found: /login
Method Not Allowed: /authentication/login/
Unauthorized: /workout
Unauthorized: /workout
Internal Server Error: /workout
Traceback (most recent call last):
  File "C:\Users\CLEVO Computer\AppData\Local\Programs\Python\Python310\lib\site-packages\django\core\handlers\exception.py", line 55, in inner
    response = get_response(request)
  File "C:\Users\CLEVO Computer\AppData\Local\Programs\Python\Python310\lib\site-packages\django\core\handlers\base.py", line 197, in _get_response
    response = wrapped_callback(request, *callback_args, **callback_kwargs)
  File "C:\Users\CLEVO Computer\AppData\Local\Programs\Python\Python310\lib\site-packages\django\views\decorators\csrf.py", line 54, in wrapped_view
    return view_func(*args, **kwargs)
  File "C:\Users\CLEVO Computer\AppData\Local\Programs\Python\Python310\lib\site-packages\django\views\generic\base.py", line 103, in view
    return self.dispatch(request, *args, **kwargs)
  File "C:\Users\CLEVO Computer\AppData\Local\Programs\Python\Python310\lib\site-packages\rest_framework\views.py", line 509, in dispatch
    response = self.handle_exception(exc)
  File "C:\Users\CLEVO Computer\AppData\Local\Programs\Python\Python310\lib\site-packages\rest_framework\views.py", line 469, in handle_exception
    self.raise_uncaught_exception(exc)
  File "C:\Users\CLEVO Computer\AppData\Local\Programs\Python\Python310\lib\site-packages\rest_framework\views.py", line 480, in raise_uncaught_exception
    raise exc
  File "C:\Users\CLEVO Computer\AppData\Local\Programs\Python\Python310\lib\site-packages\rest_framework\views.py", line 506, in dispatch
    response = handler(request, *args, **kwargs)
  File "D:\Projects\FIT\backend\src\workout\views.py", line 17, in get
    workouts = Workout.objects.filter(user = request.user.id)
  File "C:\Users\CLEVO Computer\AppData\Local\Programs\Python\Python310\lib\site-packages\django\db\models\manager.py", line 85, in manager_method
    return getattr(self.get_queryset(), name)(*args, **kwargs)
  File "C:\Users\CLEVO Computer\AppData\Local\Programs\Python\Python310\lib\site-packages\django\db\models\query.py", line 1420, in filter
    return self._filter_or_exclude(False, args, kwargs)
  File "C:\Users\CLEVO Computer\AppData\Local\Programs\Python\Python310\lib\site-packages\django\db\models\query.py", line 1438, in _filter_or_exclude
    clone._filter_or_exclude_inplace(negate, args, kwargs)
  File "C:\Users\CLEVO Computer\AppData\Local\Programs\Python\Python310\lib\site-packages\django\db\models\query.py", line 1445, in _filter_or_exclude_inplace
    self._query.add_q(Q(*args, **kwargs))
  File "C:\Users\CLEVO Computer\AppData\Local\Programs\Python\Python310\lib\site-packages\django\db\models\sql\query.py", line 1532, in add_q
    clause, _ = self._add_q(q_object, self.used_aliases)
  File "C:\Users\CLEVO Computer\AppData\Local\Programs\Python\Python310\lib\site-packages\django\db\models\sql\query.py", line 1562, in _add_q
    child_clause, needed_inner = self.build_filter(
  File "C:\Users\CLEVO Computer\AppData\Local\Programs\Python\Python310\lib\site-packages\django\db\models\sql\query.py", line 1407, in build_filter
    lookups, parts, reffed_expression = self.solve_lookup_type(arg)
  File "C:\Users\CLEVO Computer\AppData\Local\Programs\Python\Python310\lib\site-packages\django\db\models\sql\query.py", line 1217, in solve_lookup_type
    _, field, _, lookup_parts = self.names_to_path(lookup_splitted, self.get_meta())
  File "C:\Users\CLEVO Computer\AppData\Local\Programs\Python\Python310\lib\site-packages\django\db\models\sql\query.py", line 1709, in names_to_path
    raise FieldError(
django.core.exceptions.FieldError: Cannot resolve keyword 'user' into field. Choices are: author, author_id, date, exercise, history, history_id, id, length, name, note
Not Found: /workout/
Not Found: /workout/
Unauthorized: /workout
Internal Server Error: /workout
Traceback (most recent call last):
  File "C:\Users\CLEVO Computer\AppData\Local\Programs\Python\Python310\lib\site-packages\django\core\handlers\exception.py", line 55, in inner
    response = get_response(request)
  File "C:\Users\CLEVO Computer\AppData\Local\Programs\Python\Python310\lib\site-packages\django\core\handlers\base.py", line 197, in _get_response
    response = wrapped_callback(request, *callback_args, **callback_kwargs)
  File "C:\Users\CLEVO Computer\AppData\Local\Programs\Python\Python310\lib\site-packages\django\views\decorators\csrf.py", line 54, in wrapped_view
    return view_func(*args, **kwargs)
  File "C:\Users\CLEVO Computer\AppData\Local\Programs\Python\Python310\lib\site-packages\django\views\generic\base.py", line 103, in view
    return self.dispatch(request, *args, **kwargs)
  File "C:\Users\CLEVO Computer\AppData\Local\Programs\Python\Python310\lib\site-packages\rest_framework\views.py", line 509, in dispatch
    response = self.handle_exception(exc)
  File "C:\Users\CLEVO Computer\AppData\Local\Programs\Python\Python310\lib\site-packages\rest_framework\views.py", line 469, in handle_exception
    self.raise_uncaught_exception(exc)
  File "C:\Users\CLEVO Computer\AppData\Local\Programs\Python\Python310\lib\site-packages\rest_framework\views.py", line 480, in raise_uncaught_exception
    raise exc
  File "C:\Users\CLEVO Computer\AppData\Local\Programs\Python\Python310\lib\site-packages\rest_framework\views.py", line 506, in dispatch
    response = handler(request, *args, **kwargs)
  File "D:\Projects\FIT\backend\src\workout\views.py", line 17, in get
    workouts = Workout.objects.filter(user = request.user.id)
  File "C:\Users\CLEVO Computer\AppData\Local\Programs\Python\Python310\lib\site-packages\django\db\models\manager.py", line 85, in manager_method
    return getattr(self.get_queryset(), name)(*args, **kwargs)
  File "C:\Users\CLEVO Computer\AppData\Local\Programs\Python\Python310\lib\site-packages\django\db\models\query.py", line 1420, in filter
    return self._filter_or_exclude(False, args, kwargs)
  File "C:\Users\CLEVO Computer\AppData\Local\Programs\Python\Python310\lib\site-packages\django\db\models\query.py", line 1438, in _filter_or_exclude
    clone._filter_or_exclude_inplace(negate, args, kwargs)
  File "C:\Users\CLEVO Computer\AppData\Local\Programs\Python\Python310\lib\site-packages\django\db\models\query.py", line 1445, in _filter_or_exclude_inplace
    self._query.add_q(Q(*args, **kwargs))
  File "C:\Users\CLEVO Computer\AppData\Local\Programs\Python\Python310\lib\site-packages\django\db\models\sql\query.py", line 1532, in add_q
    clause, _ = self._add_q(q_object, self.used_aliases)
  File "C:\Users\CLEVO Computer\AppData\Local\Programs\Python\Python310\lib\site-packages\django\db\models\sql\query.py", line 1562, in _add_q
    child_clause, needed_inner = self.build_filter(
  File "C:\Users\CLEVO Computer\AppData\Local\Programs\Python\Python310\lib\site-packages\django\db\models\sql\query.py", line 1407, in build_filter
    lookups, parts, reffed_expression = self.solve_lookup_type(arg)
  File "C:\Users\CLEVO Computer\AppData\Local\Programs\Python\Python310\lib\site-packages\django\db\models\sql\query.py", line 1217, in solve_lookup_type
    _, field, _, lookup_parts = self.names_to_path(lookup_splitted, self.get_meta())
  File "C:\Users\CLEVO Computer\AppData\Local\Programs\Python\Python310\lib\site-packages\django\db\models\sql\query.py", line 1709, in names_to_path
    raise FieldError(
django.core.exceptions.FieldError: Cannot resolve keyword 'user' into field. Choices are: author, author_id, date, exercise, history, history_id, id, length, name, note
Unauthorized: /workout/
Not Found: /workout/workout
Unauthorized: /workout/
Internal Server Error: /workout/
Traceback (most recent call last):
  File "C:\Users\CLEVO Computer\AppData\Local\Programs\Python\Python310\lib\site-packages\django\core\handlers\exception.py", line 55, in inner
    response = get_response(request)
  File "C:\Users\CLEVO Computer\AppData\Local\Programs\Python\Python310\lib\site-packages\django\core\handlers\base.py", line 197, in _get_response
    response = wrapped_callback(request, *callback_args, **callback_kwargs)
  File "C:\Users\CLEVO Computer\AppData\Local\Programs\Python\Python310\lib\site-packages\django\views\decorators\csrf.py", line 54, in wrapped_view
    return view_func(*args, **kwargs)
  File "C:\Users\CLEVO Computer\AppData\Local\Programs\Python\Python310\lib\site-packages\django\views\generic\base.py", line 103, in view
    return self.dispatch(request, *args, **kwargs)
  File "C:\Users\CLEVO Computer\AppData\Local\Programs\Python\Python310\lib\site-packages\rest_framework\views.py", line 509, in dispatch
    response = self.handle_exception(exc)
  File "C:\Users\CLEVO Computer\AppData\Local\Programs\Python\Python310\lib\site-packages\rest_framework\views.py", line 469, in handle_exception
    self.raise_uncaught_exception(exc)
  File "C:\Users\CLEVO Computer\AppData\Local\Programs\Python\Python310\lib\site-packages\rest_framework\views.py", line 480, in raise_uncaught_exception
    raise exc
  File "C:\Users\CLEVO Computer\AppData\Local\Programs\Python\Python310\lib\site-packages\rest_framework\views.py", line 506, in dispatch
    response = handler(request, *args, **kwargs)
  File "D:\Projects\FIT\backend\src\workout\views.py", line 17, in get
    workouts = Workout.objects.filter(user = request.user.id)
  File "C:\Users\CLEVO Computer\AppData\Local\Programs\Python\Python310\lib\site-packages\django\db\models\manager.py", line 85, in manager_method
    return getattr(self.get_queryset(), name)(*args, **kwargs)
  File "C:\Users\CLEVO Computer\AppData\Local\Programs\Python\Python310\lib\site-packages\django\db\models\query.py", line 1420, in filter
    return self._filter_or_exclude(False, args, kwargs)
  File "C:\Users\CLEVO Computer\AppData\Local\Programs\Python\Python310\lib\site-packages\django\db\models\query.py", line 1438, in _filter_or_exclude
    clone._filter_or_exclude_inplace(negate, args, kwargs)
  File "C:\Users\CLEVO Computer\AppData\Local\Programs\Python\Python310\lib\site-packages\django\db\models\query.py", line 1445, in _filter_or_exclude_inplace
    self._query.add_q(Q(*args, **kwargs))
  File "C:\Users\CLEVO Computer\AppData\Local\Programs\Python\Python310\lib\site-packages\django\db\models\sql\query.py", line 1532, in add_q
    clause, _ = self._add_q(q_object, self.used_aliases)
  File "C:\Users\CLEVO Computer\AppData\Local\Programs\Python\Python310\lib\site-packages\django\db\models\sql\query.py", line 1562, in _add_q
    child_clause, needed_inner = self.build_filter(
  File "C:\Users\CLEVO Computer\AppData\Local\Programs\Python\Python310\lib\site-packages\django\db\models\sql\query.py", line 1407, in build_filter
    lookups, parts, reffed_expression = self.solve_lookup_type(arg)
  File "C:\Users\CLEVO Computer\AppData\Local\Programs\Python\Python310\lib\site-packages\django\db\models\sql\query.py", line 1217, in solve_lookup_type
    _, field, _, lookup_parts = self.names_to_path(lookup_splitted, self.get_meta())
  File "C:\Users\CLEVO Computer\AppData\Local\Programs\Python\Python310\lib\site-packages\django\db\models\sql\query.py", line 1709, in names_to_path
    raise FieldError(
django.core.exceptions.FieldError: Cannot resolve keyword 'user' into field. Choices are: author, author_id, date, exercise, history, history_id, id, length, name, note
Internal Server Error: /workout/
Traceback (most recent call last):
  File "C:\Users\CLEVO Computer\AppData\Local\Programs\Python\Python310\lib\site-packages\django\core\handlers\exception.py", line 55, in inner
    response = get_response(request)
  File "C:\Users\CLEVO Computer\AppData\Local\Programs\Python\Python310\lib\site-packages\django\core\handlers\base.py", line 197, in _get_response
    response = wrapped_callback(request, *callback_args, **callback_kwargs)
  File "C:\Users\CLEVO Computer\AppData\Local\Programs\Python\Python310\lib\site-packages\django\views\decorators\csrf.py", line 54, in wrapped_view
    return view_func(*args, **kwargs)
  File "C:\Users\CLEVO Computer\AppData\Local\Programs\Python\Python310\lib\site-packages\django\views\generic\base.py", line 103, in view
    return self.dispatch(request, *args, **kwargs)
  File "C:\Users\CLEVO Computer\AppData\Local\Programs\Python\Python310\lib\site-packages\rest_framework\views.py", line 509, in dispatch
    response = self.handle_exception(exc)
  File "C:\Users\CLEVO Computer\AppData\Local\Programs\Python\Python310\lib\site-packages\rest_framework\views.py", line 469, in handle_exception
    self.raise_uncaught_exception(exc)
  File "C:\Users\CLEVO Computer\AppData\Local\Programs\Python\Python310\lib\site-packages\rest_framework\views.py", line 480, in raise_uncaught_exception
    raise exc
  File "C:\Users\CLEVO Computer\AppData\Local\Programs\Python\Python310\lib\site-packages\rest_framework\views.py", line 506, in dispatch
    response = handler(request, *args, **kwargs)
  File "D:\Projects\FIT\backend\src\workout\views.py", line 17, in get
    workouts = Workout.objects.filter(user = request.user.id)
  File "C:\Users\CLEVO Computer\AppData\Local\Programs\Python\Python310\lib\site-packages\django\db\models\manager.py", line 85, in manager_method
    return getattr(self.get_queryset(), name)(*args, **kwargs)
  File "C:\Users\CLEVO Computer\AppData\Local\Programs\Python\Python310\lib\site-packages\django\db\models\query.py", line 1420, in filter
    return self._filter_or_exclude(False, args, kwargs)
  File "C:\Users\CLEVO Computer\AppData\Local\Programs\Python\Python310\lib\site-packages\django\db\models\query.py", line 1438, in _filter_or_exclude
    clone._filter_or_exclude_inplace(negate, args, kwargs)
  File "C:\Users\CLEVO Computer\AppData\Local\Programs\Python\Python310\lib\site-packages\django\db\models\query.py", line 1445, in _filter_or_exclude_inplace
    self._query.add_q(Q(*args, **kwargs))
  File "C:\Users\CLEVO Computer\AppData\Local\Programs\Python\Python310\lib\site-packages\django\db\models\sql\query.py", line 1532, in add_q
    clause, _ = self._add_q(q_object, self.used_aliases)
  File "C:\Users\CLEVO Computer\AppData\Local\Programs\Python\Python310\lib\site-packages\django\db\models\sql\query.py", line 1562, in _add_q
    child_clause, needed_inner = self.build_filter(
  File "C:\Users\CLEVO Computer\AppData\Local\Programs\Python\Python310\lib\site-packages\django\db\models\sql\query.py", line 1407, in build_filter
    lookups, parts, reffed_expression = self.solve_lookup_type(arg)
  File "C:\Users\CLEVO Computer\AppData\Local\Programs\Python\Python310\lib\site-packages\django\db\models\sql\query.py", line 1217, in solve_lookup_type
    _, field, _, lookup_parts = self.names_to_path(lookup_splitted, self.get_meta())
  File "C:\Users\CLEVO Computer\AppData\Local\Programs\Python\Python310\lib\site-packages\django\db\models\sql\query.py", line 1709, in names_to_path
    raise FieldError(
django.core.exceptions.FieldError: Cannot resolve keyword 'user' into field. Choices are: author, author_id, date, exercise, history, history_id, id, length, name, note
Unauthorized: /workout/
Unauthorized: /workout/
Internal Server Error: /workout/
Traceback (most recent call last):
  File "C:\Users\CLEVO Computer\AppData\Local\Programs\Python\Python310\lib\site-packages\django\core\handlers\exception.py", line 55, in inner
    response = get_response(request)
  File "C:\Users\CLEVO Computer\AppData\Local\Programs\Python\Python310\lib\site-packages\django\core\handlers\base.py", line 197, in _get_response
    response = wrapped_callback(request, *callback_args, **callback_kwargs)
  File "C:\Users\CLEVO Computer\AppData\Local\Programs\Python\Python310\lib\site-packages\django\views\decorators\csrf.py", line 54, in wrapped_view
    return view_func(*args, **kwargs)
  File "C:\Users\CLEVO Computer\AppData\Local\Programs\Python\Python310\lib\site-packages\django\views\generic\base.py", line 103, in view
    return self.dispatch(request, *args, **kwargs)
  File "C:\Users\CLEVO Computer\AppData\Local\Programs\Python\Python310\lib\site-packages\rest_framework\views.py", line 509, in dispatch
    response = self.handle_exception(exc)
  File "C:\Users\CLEVO Computer\AppData\Local\Programs\Python\Python310\lib\site-packages\rest_framework\views.py", line 469, in handle_exception
    self.raise_uncaught_exception(exc)
  File "C:\Users\CLEVO Computer\AppData\Local\Programs\Python\Python310\lib\site-packages\rest_framework\views.py", line 480, in raise_uncaught_exception
    raise exc
  File "C:\Users\CLEVO Computer\AppData\Local\Programs\Python\Python310\lib\site-packages\rest_framework\views.py", line 506, in dispatch
    response = handler(request, *args, **kwargs)
  File "D:\Projects\FIT\backend\src\workout\views.py", line 17, in get
    workouts = Workout.objects.filter(user = request.user.id)
  File "C:\Users\CLEVO Computer\AppData\Local\Programs\Python\Python310\lib\site-packages\django\db\models\manager.py", line 85, in manager_method
    return getattr(self.get_queryset(), name)(*args, **kwargs)
  File "C:\Users\CLEVO Computer\AppData\Local\Programs\Python\Python310\lib\site-packages\django\db\models\query.py", line 1420, in filter
    return self._filter_or_exclude(False, args, kwargs)
  File "C:\Users\CLEVO Computer\AppData\Local\Programs\Python\Python310\lib\site-packages\django\db\models\query.py", line 1438, in _filter_or_exclude
    clone._filter_or_exclude_inplace(negate, args, kwargs)
  File "C:\Users\CLEVO Computer\AppData\Local\Programs\Python\Python310\lib\site-packages\django\db\models\query.py", line 1445, in _filter_or_exclude_inplace
    self._query.add_q(Q(*args, **kwargs))
  File "C:\Users\CLEVO Computer\AppData\Local\Programs\Python\Python310\lib\site-packages\django\db\models\sql\query.py", line 1532, in add_q
    clause, _ = self._add_q(q_object, self.used_aliases)
  File "C:\Users\CLEVO Computer\AppData\Local\Programs\Python\Python310\lib\site-packages\django\db\models\sql\query.py", line 1562, in _add_q
    child_clause, needed_inner = self.build_filter(
  File "C:\Users\CLEVO Computer\AppData\Local\Programs\Python\Python310\lib\site-packages\django\db\models\sql\query.py", line 1407, in build_filter
    lookups, parts, reffed_expression = self.solve_lookup_type(arg)
  File "C:\Users\CLEVO Computer\AppData\Local\Programs\Python\Python310\lib\site-packages\django\db\models\sql\query.py", line 1217, in solve_lookup_type
    _, field, _, lookup_parts = self.names_to_path(lookup_splitted, self.get_meta())
  File "C:\Users\CLEVO Computer\AppData\Local\Programs\Python\Python310\lib\site-packages\django\db\models\sql\query.py", line 1709, in names_to_path
    raise FieldError(
django.core.exceptions.FieldError: Cannot resolve keyword 'user' into field. Choices are: author, author_id, date, exercise, history, history_id, id, length, name, note
Unauthorized: /exercise/
Unauthorized: /exercise/
Method Not Allowed: /authentication/login/
Internal Server Error: /workout/
Traceback (most recent call last):
  File "C:\Users\CLEVO Computer\AppData\Local\Programs\Python\Python310\lib\site-packages\django\core\handlers\exception.py", line 55, in inner
    response = get_response(request)
  File "C:\Users\CLEVO Computer\AppData\Local\Programs\Python\Python310\lib\site-packages\django\core\handlers\base.py", line 197, in _get_response
    response = wrapped_callback(request, *callback_args, **callback_kwargs)
  File "C:\Users\CLEVO Computer\AppData\Local\Programs\Python\Python310\lib\site-packages\django\views\decorators\csrf.py", line 54, in wrapped_view
    return view_func(*args, **kwargs)
  File "C:\Users\CLEVO Computer\AppData\Local\Programs\Python\Python310\lib\site-packages\django\views\generic\base.py", line 103, in view
    return self.dispatch(request, *args, **kwargs)
  File "C:\Users\CLEVO Computer\AppData\Local\Programs\Python\Python310\lib\site-packages\rest_framework\views.py", line 509, in dispatch
    response = self.handle_exception(exc)
  File "C:\Users\CLEVO Computer\AppData\Local\Programs\Python\Python310\lib\site-packages\rest_framework\views.py", line 469, in handle_exception
    self.raise_uncaught_exception(exc)
  File "C:\Users\CLEVO Computer\AppData\Local\Programs\Python\Python310\lib\site-packages\rest_framework\views.py", line 480, in raise_uncaught_exception
    raise exc
  File "C:\Users\CLEVO Computer\AppData\Local\Programs\Python\Python310\lib\site-packages\rest_framework\views.py", line 506, in dispatch
    response = handler(request, *args, **kwargs)
  File "D:\Projects\FIT\backend\src\workout\views.py", line 17, in get
    workouts = Workout.objects.filter(user = request.user.id)
  File "C:\Users\CLEVO Computer\AppData\Local\Programs\Python\Python310\lib\site-packages\django\db\models\manager.py", line 85, in manager_method
    return getattr(self.get_queryset(), name)(*args, **kwargs)
  File "C:\Users\CLEVO Computer\AppData\Local\Programs\Python\Python310\lib\site-packages\django\db\models\query.py", line 1420, in filter
    return self._filter_or_exclude(False, args, kwargs)
  File "C:\Users\CLEVO Computer\AppData\Local\Programs\Python\Python310\lib\site-packages\django\db\models\query.py", line 1438, in _filter_or_exclude
    clone._filter_or_exclude_inplace(negate, args, kwargs)
  File "C:\Users\CLEVO Computer\AppData\Local\Programs\Python\Python310\lib\site-packages\django\db\models\query.py", line 1445, in _filter_or_exclude_inplace
    self._query.add_q(Q(*args, **kwargs))
  File "C:\Users\CLEVO Computer\AppData\Local\Programs\Python\Python310\lib\site-packages\django\db\models\sql\query.py", line 1532, in add_q
    clause, _ = self._add_q(q_object, self.used_aliases)
  File "C:\Users\CLEVO Computer\AppData\Local\Programs\Python\Python310\lib\site-packages\django\db\models\sql\query.py", line 1562, in _add_q
    child_clause, needed_inner = self.build_filter(
  File "C:\Users\CLEVO Computer\AppData\Local\Programs\Python\Python310\lib\site-packages\django\db\models\sql\query.py", line 1407, in build_filter
    lookups, parts, reffed_expression = self.solve_lookup_type(arg)
  File "C:\Users\CLEVO Computer\AppData\Local\Programs\Python\Python310\lib\site-packages\django\db\models\sql\query.py", line 1217, in solve_lookup_type
    _, field, _, lookup_parts = self.names_to_path(lookup_splitted, self.get_meta())
  File "C:\Users\CLEVO Computer\AppData\Local\Programs\Python\Python310\lib\site-packages\django\db\models\sql\query.py", line 1709, in names_to_path
    raise FieldError(
django.core.exceptions.FieldError: Cannot resolve keyword 'user' into field. Choices are: author, author_id, date, exercise, history, history_id, id, length, name, note
Not Found: /workout/exercise/
Not Found: /workout/exercise
Internal Server Error: /workouts/
Traceback (most recent call last):
  File "C:\Users\CLEVO Computer\AppData\Local\Programs\Python\Python310\lib\site-packages\django\core\handlers\exception.py", line 55, in inner
    response = get_response(request)
  File "C:\Users\CLEVO Computer\AppData\Local\Programs\Python\Python310\lib\site-packages\django\core\handlers\base.py", line 197, in _get_response
    response = wrapped_callback(request, *callback_args, **callback_kwargs)
  File "C:\Users\CLEVO Computer\AppData\Local\Programs\Python\Python310\lib\site-packages\django\views\decorators\csrf.py", line 54, in wrapped_view
    return view_func(*args, **kwargs)
  File "C:\Users\CLEVO Computer\AppData\Local\Programs\Python\Python310\lib\site-packages\django\views\generic\base.py", line 103, in view
    return self.dispatch(request, *args, **kwargs)
  File "C:\Users\CLEVO Computer\AppData\Local\Programs\Python\Python310\lib\site-packages\rest_framework\views.py", line 509, in dispatch
    response = self.handle_exception(exc)
  File "C:\Users\CLEVO Computer\AppData\Local\Programs\Python\Python310\lib\site-packages\rest_framework\views.py", line 469, in handle_exception
    self.raise_uncaught_exception(exc)
  File "C:\Users\CLEVO Computer\AppData\Local\Programs\Python\Python310\lib\site-packages\rest_framework\views.py", line 480, in raise_uncaught_exception
    raise exc
  File "C:\Users\CLEVO Computer\AppData\Local\Programs\Python\Python310\lib\site-packages\rest_framework\views.py", line 506, in dispatch
    response = handler(request, *args, **kwargs)
  File "D:\Projects\FIT\backend\src\workout\views.py", line 17, in get
    workouts = Workout.objects.filter(user = request.user.id)
  File "C:\Users\CLEVO Computer\AppData\Local\Programs\Python\Python310\lib\site-packages\django\db\models\manager.py", line 85, in manager_method
    return getattr(self.get_queryset(), name)(*args, **kwargs)
  File "C:\Users\CLEVO Computer\AppData\Local\Programs\Python\Python310\lib\site-packages\django\db\models\query.py", line 1420, in filter
    return self._filter_or_exclude(False, args, kwargs)
  File "C:\Users\CLEVO Computer\AppData\Local\Programs\Python\Python310\lib\site-packages\django\db\models\query.py", line 1438, in _filter_or_exclude
    clone._filter_or_exclude_inplace(negate, args, kwargs)
  File "C:\Users\CLEVO Computer\AppData\Local\Programs\Python\Python310\lib\site-packages\django\db\models\query.py", line 1445, in _filter_or_exclude_inplace
    self._query.add_q(Q(*args, **kwargs))
  File "C:\Users\CLEVO Computer\AppData\Local\Programs\Python\Python310\lib\site-packages\django\db\models\sql\query.py", line 1532, in add_q
    clause, _ = self._add_q(q_object, self.used_aliases)
  File "C:\Users\CLEVO Computer\AppData\Local\Programs\Python\Python310\lib\site-packages\django\db\models\sql\query.py", line 1562, in _add_q
    child_clause, needed_inner = self.build_filter(
  File "C:\Users\CLEVO Computer\AppData\Local\Programs\Python\Python310\lib\site-packages\django\db\models\sql\query.py", line 1407, in build_filter
    lookups, parts, reffed_expression = self.solve_lookup_type(arg)
  File "C:\Users\CLEVO Computer\AppData\Local\Programs\Python\Python310\lib\site-packages\django\db\models\sql\query.py", line 1217, in solve_lookup_type
    _, field, _, lookup_parts = self.names_to_path(lookup_splitted, self.get_meta())
  File "C:\Users\CLEVO Computer\AppData\Local\Programs\Python\Python310\lib\site-packages\django\db\models\sql\query.py", line 1709, in names_to_path
    raise FieldError(
django.core.exceptions.FieldError: Cannot resolve keyword 'user' into field. Choices are: author, author_id, date, exercise, history, history_id, id, length, name, note
Unauthorized: /workouts/
Internal Server Error: /workouts/
Traceback (most recent call last):
  File "C:\Users\CLEVO Computer\AppData\Local\Programs\Python\Python310\lib\site-packages\django\core\handlers\exception.py", line 55, in inner
    response = get_response(request)
  File "C:\Users\CLEVO Computer\AppData\Local\Programs\Python\Python310\lib\site-packages\django\core\handlers\base.py", line 197, in _get_response
    response = wrapped_callback(request, *callback_args, **callback_kwargs)
  File "C:\Users\CLEVO Computer\AppData\Local\Programs\Python\Python310\lib\site-packages\django\views\decorators\csrf.py", line 54, in wrapped_view
    return view_func(*args, **kwargs)
  File "C:\Users\CLEVO Computer\AppData\Local\Programs\Python\Python310\lib\site-packages\django\views\generic\base.py", line 103, in view
    return self.dispatch(request, *args, **kwargs)
  File "C:\Users\CLEVO Computer\AppData\Local\Programs\Python\Python310\lib\site-packages\rest_framework\views.py", line 509, in dispatch
    response = self.handle_exception(exc)
  File "C:\Users\CLEVO Computer\AppData\Local\Programs\Python\Python310\lib\site-packages\rest_framework\views.py", line 469, in handle_exception
    self.raise_uncaught_exception(exc)
  File "C:\Users\CLEVO Computer\AppData\Local\Programs\Python\Python310\lib\site-packages\rest_framework\views.py", line 480, in raise_uncaught_exception
    raise exc
  File "C:\Users\CLEVO Computer\AppData\Local\Programs\Python\Python310\lib\site-packages\rest_framework\views.py", line 506, in dispatch
    response = handler(request, *args, **kwargs)
  File "D:\Projects\FIT\backend\src\workout\views.py", line 17, in get
    workouts = Workout.objects.filter(user = request.user.id)
  File "C:\Users\CLEVO Computer\AppData\Local\Programs\Python\Python310\lib\site-packages\django\db\models\manager.py", line 85, in manager_method
    return getattr(self.get_queryset(), name)(*args, **kwargs)
  File "C:\Users\CLEVO Computer\AppData\Local\Programs\Python\Python310\lib\site-packages\django\db\models\query.py", line 1420, in filter
    return self._filter_or_exclude(False, args, kwargs)
  File "C:\Users\CLEVO Computer\AppData\Local\Programs\Python\Python310\lib\site-packages\django\db\models\query.py", line 1438, in _filter_or_exclude
    clone._filter_or_exclude_inplace(negate, args, kwargs)
  File "C:\Users\CLEVO Computer\AppData\Local\Programs\Python\Python310\lib\site-packages\django\db\models\query.py", line 1445, in _filter_or_exclude_inplace
    self._query.add_q(Q(*args, **kwargs))
  File "C:\Users\CLEVO Computer\AppData\Local\Programs\Python\Python310\lib\site-packages\django\db\models\sql\query.py", line 1532, in add_q
    clause, _ = self._add_q(q_object, self.used_aliases)
  File "C:\Users\CLEVO Computer\AppData\Local\Programs\Python\Python310\lib\site-packages\django\db\models\sql\query.py", line 1562, in _add_q
    child_clause, needed_inner = self.build_filter(
  File "C:\Users\CLEVO Computer\AppData\Local\Programs\Python\Python310\lib\site-packages\django\db\models\sql\query.py", line 1407, in build_filter
    lookups, parts, reffed_expression = self.solve_lookup_type(arg)
  File "C:\Users\CLEVO Computer\AppData\Local\Programs\Python\Python310\lib\site-packages\django\db\models\sql\query.py", line 1217, in solve_lookup_type
    _, field, _, lookup_parts = self.names_to_path(lookup_splitted, self.get_meta())
  File "C:\Users\CLEVO Computer\AppData\Local\Programs\Python\Python310\lib\site-packages\django\db\models\sql\query.py", line 1709, in names_to_path
    raise FieldError(
django.core.exceptions.FieldError: Cannot resolve keyword 'user' into field. Choices are: author, author_id, date, exercise, history, history_id, id, length, name, note
Internal Server Error: /workouts/
Traceback (most recent call last):
  File "C:\Users\CLEVO Computer\AppData\Local\Programs\Python\Python310\lib\site-packages\django\core\handlers\exception.py", line 55, in inner
    response = get_response(request)
  File "C:\Users\CLEVO Computer\AppData\Local\Programs\Python\Python310\lib\site-packages\django\core\handlers\base.py", line 197, in _get_response
    response = wrapped_callback(request, *callback_args, **callback_kwargs)
  File "C:\Users\CLEVO Computer\AppData\Local\Programs\Python\Python310\lib\site-packages\django\views\decorators\csrf.py", line 54, in wrapped_view
    return view_func(*args, **kwargs)
  File "C:\Users\CLEVO Computer\AppData\Local\Programs\Python\Python310\lib\site-packages\django\views\generic\base.py", line 103, in view
    return self.dispatch(request, *args, **kwargs)
  File "C:\Users\CLEVO Computer\AppData\Local\Programs\Python\Python310\lib\site-packages\rest_framework\views.py", line 509, in dispatch
    response = self.handle_exception(exc)
  File "C:\Users\CLEVO Computer\AppData\Local\Programs\Python\Python310\lib\site-packages\rest_framework\views.py", line 469, in handle_exception
    self.raise_uncaught_exception(exc)
  File "C:\Users\CLEVO Computer\AppData\Local\Programs\Python\Python310\lib\site-packages\rest_framework\views.py", line 480, in raise_uncaught_exception
    raise exc
  File "C:\Users\CLEVO Computer\AppData\Local\Programs\Python\Python310\lib\site-packages\rest_framework\views.py", line 506, in dispatch
    response = handler(request, *args, **kwargs)
  File "D:\Projects\FIT\backend\src\workout\views.py", line 17, in get
    workouts = Workout.objects.filter(user = request.user.id)
  File "C:\Users\CLEVO Computer\AppData\Local\Programs\Python\Python310\lib\site-packages\django\db\models\manager.py", line 85, in manager_method
    return getattr(self.get_queryset(), name)(*args, **kwargs)
  File "C:\Users\CLEVO Computer\AppData\Local\Programs\Python\Python310\lib\site-packages\django\db\models\query.py", line 1420, in filter
    return self._filter_or_exclude(False, args, kwargs)
  File "C:\Users\CLEVO Computer\AppData\Local\Programs\Python\Python310\lib\site-packages\django\db\models\query.py", line 1438, in _filter_or_exclude
    clone._filter_or_exclude_inplace(negate, args, kwargs)
  File "C:\Users\CLEVO Computer\AppData\Local\Programs\Python\Python310\lib\site-packages\django\db\models\query.py", line 1445, in _filter_or_exclude_inplace
    self._query.add_q(Q(*args, **kwargs))
  File "C:\Users\CLEVO Computer\AppData\Local\Programs\Python\Python310\lib\site-packages\django\db\models\sql\query.py", line 1532, in add_q
    clause, _ = self._add_q(q_object, self.used_aliases)
  File "C:\Users\CLEVO Computer\AppData\Local\Programs\Python\Python310\lib\site-packages\django\db\models\sql\query.py", line 1562, in _add_q
    child_clause, needed_inner = self.build_filter(
  File "C:\Users\CLEVO Computer\AppData\Local\Programs\Python\Python310\lib\site-packages\django\db\models\sql\query.py", line 1407, in build_filter
    lookups, parts, reffed_expression = self.solve_lookup_type(arg)
  File "C:\Users\CLEVO Computer\AppData\Local\Programs\Python\Python310\lib\site-packages\django\db\models\sql\query.py", line 1217, in solve_lookup_type
    _, field, _, lookup_parts = self.names_to_path(lookup_splitted, self.get_meta())
  File "C:\Users\CLEVO Computer\AppData\Local\Programs\Python\Python310\lib\site-packages\django\db\models\sql\query.py", line 1709, in names_to_path
    raise FieldError(
django.core.exceptions.FieldError: Cannot resolve keyword 'user' into field. Choices are: author, author_id, date, exercise, history, history_id, id, length, name, note
Not Found: /workout/workouts/
Not Found: /workout/
Method Not Allowed: /authentication/register/
Bad Request: /authentication/register/
Bad Request: /authentication/register/
Bad Request: /authentication/register/
Bad Request: /authentication/register/
Bad Request: /authentication/register/
Method Not Allowed: /authentication/login/
Not Found: /
